Workbook

Sheet 项目提成核算表
A1: 项目名称 | B1: 项目金额 | C1: 项目成本比例 | D1: 项目成本红线 | E1: UIUE | F1: 产品提成比例 | G1: 产品提成金额 | H1: 开发人员数量 | I1: 项目周期（月） | J1: 开发人员 | K1: 开发奖金比例 | L1: 开发奖金池 | M1: 开发每人奖金 | N1: 开发每人每月奖金 | O1: 项目实际成本 | P1: 项目预估利润 | Q1: 地区 | R1: 商务经理 | S1: 项目签单时间 | T1: UI确认时间 | U1: 工期 | V1: 理论验收日期 | W1: 实际交付日期 | X1: 已回款1 | Y1: 已回款2 | Z1: 已回款3 | AA1: 已回款4 | AB1: 付款方式 | AC1: 备注 | AD1: IP
A2: 报告查询H5 | B2: 3000 | C2: 0.35 | D2: =B2*C2 -> 1050 | E2: 原粼 | F2: 0 | G2: =B2*F2 -> 0 | H2: 1 | I2: 0.33 | J2: 原粼 | K2: 0.05 | L2: =B2*K2 -> 150 | M2: =L2/H2 -> 150 | N2: =M2/I2 -> 454.54545 | O2: =8000*H2*I2+G2+L2 -> 2790 | P2: =D2-O2 -> -1740 | Q2: 郑州 | R2: 靳林 | S2: 46056 | T2: 46062 | U2: 10工作日 | V2: =WORKDAY(T2,SUBSTITUTE(U2,"工作日","")) -> 46076 | W2: 46067 | X2: 1500 | Y2: 1500 | Z2: ~ | AA2: ~ | AB2: 50%50% | AD2: 43.248.0.138
A3: ↘报告查询H5-增项1 | B3: 500 | C3: 0.35 | D3: =B3*C3 -> 175 | E3: 原粼 | F3: 0 | G3: =B3*F3 -> 0 | H3: 1 | I3: 0.05 | J3: 原粼 | K3: 0.05 | L3: =B3*K3 -> 25 | M3: =L3/H3 -> 25 | N3: =M3/I3 -> 500 | O3: =8000*H3*I3+G3+L3 -> 425 | P3: =D3-O3 -> -250 | Q3: 郑州 | R3: 靳林 | S3: 46077 | T3: 46077 | U3: 1工作日 | V3: =WORKDAY(T3,SUBSTITUTE(U3,"工作日","")) -> 46078 | W3: 46078 | X3: 500 | Y3: ~ | Z3: ~ | AA3: ~ | AB3: 1 | AC3: 新增编号自增长
A4: ↘报告查询H5-增项2 | B4: 2500 | C4: 0.35 | D4: =B4*C4 -> 875 | E4: 原粼 | F4: 0 | G4: =B4*F4 -> 0 | H4: 1 | I4: 0.05 | J4: 原粼 | K4: 0.05 | L4: =B4*K4 -> 125 | M4: =L4/H4 -> 125 | N4: =M4/I4 -> 2500 | O4: =8000*H4*I4+G4+L4 -> 525 | P4: =D4-O4 -> 350 | Q4: 郑州 | R4: 靳林 | S4: 46083 | T4: 46083 | U4: 7工作日 | V4: =WORKDAY(T4,SUBSTITUTE(U4,"工作日","")) -> 46092 | W4: 46091 | X4: 2500 | Y4: ~ | Z4: ~ | AA4: ~ | AB4: 1 | AC4: 📄会议纪要需修改需求总结
A5: ↘报告查询H5-增项3 | B5: 1000 | C5: 0.35 | D5: =B5*C5 -> 350 | E5: 原粼 | F5: 0 | G5: =B5*F5 -> 0 | H5: 1 | I5: 0.05 | J5: 原粼 | K5: 0.05 | L5: =B5*K5 -> 50 | M5: =L5/H5 -> 50 | N5: =M5/I5 -> 1000 | O5: =8000*H5*I5+G5+L5 -> 450 | P5: =D5-O5 -> -100 | Q5: 郑州 | R5: 靳林 | S5: 46109 | T5: 46109 | U5: 2工作日 | V5: =WORKDAY(T5,SUBSTITUTE(U5,"工作日","")) -> 46112 | W5: 46111 | X5: 1000 | Y5: ~ | Z5: ~ | AA5: ~ | AB5: 1 | AC5: 跟郑老师沟通的，新增内容3点 1.增加导出功能 2.增加报告状态 3.报告管理页面:增加合伙人字段
A6: AI古玩知识问答 | B6: 22000 | C6: 0.35 | D6: =B6*C6 -> 7700 | E6: 原粼 | F6: 0.002 | G6: =B6*F6 -> 44 | H6: 1 | I6: 0.083 | J6: 张耘彬 | K6: 0.05 | L6: =B6*K6 -> 1100 | M6: =L6/H6 -> 1100 | N6: =M6/I6 -> 13253.012 | O6: =人员工资!#REF!*H6*I6+G6+L6 -> #REF! | P6: =D6-O6 -> #REF! | Q6: 杭州 | R6: 董耀辉 | S6: 46085 | T6: 46097 | U6: 30工作日 | V6: =WORKDAY(T6,SUBSTITUTE(U6,"工作日","")) -> 46139 | W6: 46114 | X6: 11000 | Y6: 6600 | Z6: 4400 | AA6: ~ | AB6: 50%30%20% | AC6: 5月14日邮件交付了源码 | AD6: 没开服务器
A7: ↘AI古玩知识问答-增项1 | B7: 2000 | C7: 0.35 | D7: =B7*C7 -> 700 | E7: 张耘彬 | F7: 0.002 | G7: =B7*F7 -> 4 | H7: 1 | I7: 0.083 | J7: 张耘彬 | K7: 0.05 | L7: =B7*K7 -> 100 | M7: =L7/H7 -> 100 | N7: =M7/I7 -> 1204.8193 | O7: =人员工资!#REF!*H7*I7+G7+L7 -> #REF! | P7: =D7-O7 -> #REF! | Q7: 杭州 | R7: 董耀辉 | S7: 46108 | T7: 46108 | U7: 3工作日 | V7: =WORKDAY(T7,SUBSTITUTE(U7,"工作日","")) -> 46113 | W7: 46114 | X7: 1000 | Y7: 1000 | Z7: ~ | AA7: ~ | AB7: 50%50% | AC7: 5月14日邮件交付了源码
A8: AI会议翻译项目 | B8: =167600*40% -> 67040 | C8: 0.35 | D8: =B8*C8 -> 23464 | E8: 陈安宁+卢佳蔚 | F8: 0.002 | G8: =B8*F8 -> 134.08 | H8: 1 | I8: 2 | J8: 张耘彬 | K8: 0.05 | L8: =B8*K8 -> 3352 | M8: =L8/H8 -> 3352 | N8: =M8/I8 -> 1676 | O8: =8000*H8*I8+G8+L8 -> 19486.08 | P8: =D8-O8 -> 3977.92 | Q8: 郑州 | R8: 石亚辉/何建新 | S8: 46081 | U8: 45工作日 | X8: =50280*40% -> 20112 | AB8: 30%30%30%10% | AC8: 给五部60%
A9: AI颜值分析 & 穿搭推荐小程序项目 | B9: 45000 | C9: 0.35 | D9: =B9*C9 -> 15750 | E9: 孔阳+卢佳蔚 | F9: 0.002 | G9: =B9*F9 -> 90 | H9: 1 | I9: 1 | J9: 段雪婷 | K9: 0.05 | L9: =B9*K9 -> 2250 | M9: =L9/H9 -> 2250 | N9: =M9/I9 -> 2250 | O9: =8000*H9*I9+G9+L9 -> 10340 | P9: =D9-O9 -> 5410 | Q9: 郑州 | R9: 郭嘉宁 | S9: 46085 | T9: 46106 | U9: 35工作日 | V9: =WORKDAY(T9,SUBSTITUTE(U9,"工作日","")) -> 46155 | X9: 22500 | Y9: 13500 | Z9: 9000 | AA9: ~ | AB9: 50%30%20% | AD9: 47.99.121.98
A10: AI数据审核分析平台 | B10: 110000 | C10: 0.35 | D10: =B10*C10 -> 38500 | E10: 段雪婷 | F10: 0 | G10: =B10*F10 -> 0 | H10: 1 | I10: 1 | J10: 段雪婷 | K10: 0.1 | L10: =B10*K10 -> 11000 | M10: =L10/H10 -> 11000 | N10: =M10/I10 -> 11000 | O10: =8000*H10*I10+G10+L10 -> 19000 | P10: =D10-O10 -> 19500 | Q10: 深圳 | R10: 郭丹妮 | S10: 46104 | T10: 46108 | U10: 50工作日 | V10: =WORKDAY(T10,SUBSTITUTE(U10,"工作日","")) -> 46178 | W10: 46142 | X10: 33000 | Y10: 22000 | Z10: 44000 | AA10: 11000 | AB10: 30%20%40%10% | AC10: 四月底交付，客户认为讯飞不行，但又找不到更好的 | AD10: 8.138.44.71
A11: 工信局企业调研小程序 | B11: 5500 | C11: 0.35 | D11: =B11*C11 -> 1925 | E11: 李耀男 | F11: 0 | G11: =B11*F11 -> 0 | H11: 1 | I11: 1 | J11: 李耀男 | K11: 0.03 | L11: =B11*K11 -> 165 | M11: =L11/H11 -> 165 | N11: =M11/I11 -> 165 | O11: =8000*H11*I11+G11+L11 -> 8165 | P11: =D11-O11 -> -6240 | Q11: 郑州 | R11: 张晓旭 | S11: 46107 | T11: 46123 | U11: 7工作日 | V11: =WORKDAY(T11,SUBSTITUTE(U11,"工作日","")) -> 46133 | X11: 2750 | Z11: ~ | AA11: ~ | AB11: 50%50% | AC11: 停工函已发 | AD11: 47.93.26.214
A12: Ai医膳智评小程序 | B12: 52750 | C12: 0.35 | D12: =B12*C12 -> 18462.5 | E12: 卢佳蔚 | F12: 0.1 | G12: =L12*F12 -> 158.25 | H12: 1 | I12: 1 | J12: 李浩田 | K12: 0.03 | L12: =B12*K12 -> 1582.5 | M12: =L12/H12 -> 1582.5 | N12: =M12/I12 -> 1582.5 | O12: =8000*H12*I12+G12+L12 -> 9740.75 | P12: =D12-O12 -> 8721.75 | Q12: 深圳 | R12: 陈妍莼 | S12: 46111 | T12: 46126 | U12: 35工作日 | V12: =WORKDAY(T12,SUBSTITUTE(U12,"工作日","")) -> 46175 | W12: 46160 | X12: 26375 | Y12: 15825 | Z12: 10550 | AA12: ~ | AB12: 50%30%20% | AD12: 47.114.93.178
A13: ↘Ai医膳智评小程序-增项S1 | B13: 1500 | C13: 0.35 | D13: =B13*C13 -> 525 | E13: 卢佳蔚 | F13: 0.1 | G13: =L13*F13 -> 4.5 | H13: 1 | I13: 1 | J13: 李浩田 | K13: 0.03 | L13: =B13*K13 -> 45 | M13: =L13/H13 -> 45 | N13: =M13/I13 -> 45 | O13: =8000*H13*I13+G13+L13 -> 8049.5 | P13: =D13-O13 -> -7524.5 | R13: 陈妍莼 | S13: 46125 | T13: 46126 | U13: 7工作日 | V13: =WORKDAY(T13,SUBSTITUTE(U13,"工作日","")) -> 46135 | W13: 46160 | X13: 1500 | Y13: ~ | Z13: ~ | AA13: ~ | AB13: 1
A14: 二开服务号 | B14: 2000 | C14: 0.35 | D14: =B14*C14 -> 700 | E14: 张耘彬 | F14: 0.1 | G14: =L14*F14 -> 6 | H14: 1 | I14: 1 | J14: 张耘彬 | K14: 0.03 | L14: =B14*K14 -> 60 | M14: =L14/H14 -> 60 | N14: =M14/I14 -> 60 | O14: =8000*H14*I14+G14+L14 -> 8066 | P14: =D14-O14 -> -7366 | Q14: 郑州 | R14: 付天宇 | S14: 46114 | T14: 46114 | U14: 1工作日 | V14: =WORKDAY(T14,SUBSTITUTE(U14,"工作日","")) -> 46115 | X14: 1000 | Z14: ~ | AA14: ~ | AB14: 50%50% | AC14: 等牦牛哥再弄一套源码，到时候就不再收费了
A15: ↘二开服务号新增S1 | B15: 1000 | C15: 0.35 | D15: =B15*C15 -> 350 | E15: 张耘彬 | F15: 0.1 | G15: =L15*F15 -> 5 | H15: 1 | I15: 1 | J15: 张耘彬 | K15: 0.05 | L15: =B15*K15 -> 50 | M15: =L15/H15 -> 50 | N15: =M15/I15 -> 50 | O15: =8000*H15*I15+G15+L15 -> 8055 | P15: =D15-O15 -> -7705 | Q15: 郑州 | R15: 付天宇 | S15: 46114 | T15: 46114 | U15: 1工作日 | V15: =WORKDAY(T15,SUBSTITUTE(U15,"工作日","")) -> 46115 | X15: 500 | Y15: -500 | Z15: ~ | AA15: ~ | AB15: 50%50% | AC15: 退款了
A16: AI本地生活APP | B16: 29300 | C16: 0.35 | D16: =B16*C16 -> 10255 | E16: 刘琳琳 | F16: 0 | G16: =L16*F16 -> 0 | H16: 1 | I16: 1 | J16: 刘琳琳 | K16: 0.05 | L16: =B16*K16 -> 1465 | M16: =L16/H16 -> 1465 | N16: =M16/I16 -> 1465 | O16: =8000*H16*I16+G16+L16 -> 9465 | P16: =D16-O16 -> 790 | Q16: 深圳一 | R16: 吴文昌 | S16: 46125 | T16: 46128 | U16: 15工作日 | V16: =WORKDAY(T16,SUBSTITUTE(U16,"工作日","")) -> 46149 | W16: 46213 | X16: 17400 | Y16: 10440 | Z16: 6960 | AA16: ~ | AB16: 50%30%20% | AC16: 34800.00（项目款29300.00、软著1500、网安3000、备案1000） | AD16: 4月底上线
A17: ↘AI本地生活app-S1增项 | B17: 8800 | C17: 0.35 | D17: =B17*C17 -> 3080 | E17: 刘琳琳 | F17: 0 | G17: =L17*F17 -> 0 | H17: 1 | I17: 1 | J17: 刘琳琳 | K17: 0.05 | L17: =B17*K17 -> 440 | M17: =L17/H17 -> 440 | N17: =M17/I17 -> 440 | O17: =8000*H17*I17+G17+L17 -> 8440 | P17: =D17-O17 -> -5360 | Q17: 深圳一 | R17: 吴文昌 | S17: 46138 | T17: 46138 | U17: 5工作日 | V17: =WORKDAY(T17,SUBSTITUTE(U17,"工作日","")) -> 46143 | W17: 46213 | X17: 5300 | Y17: 3500 | Z17: ~ | AA17: ~ | AB17: 60%40%
A18: ↘AI本地生活app-S2增项 | B18: 8000 | C18: 0.35 | D18: =B18*C18 -> 2800 | E18: 刘琳琳 | F18: 0 | G18: =L18*F18 -> 0 | H18: 1 | I18: 1 | J18: 刘琳琳 | K18: 0.05 | L18: =B18*K18 -> 400 | M18: =L18/H18 -> 400 | N18: =M18/I18 -> 400 | O18: =8000*H18*I18+G18+L18 -> 8400 | P18: =D18-O18 -> -5600 | Q18: 深圳一 | R18: 吴文昌 | S18: 46139 | T18: 46139 | U18: 5工作日 | V18: =WORKDAY(T18,SUBSTITUTE(U18,"工作日","")) -> 46146 | W18: 46213 | X18: 4000 | Y18: ~ | Z18: ~ | AA18: ~ | AB18: 60%40% | AC18: 1、项目的尾款是6960 2、ai的增项尾款是3500 3、美团的增项尾款是-800 （已收4800，扣除美团跳转app——1000；扣除用户注册登录短信验证3000） 总的项目尾款是：9660
A19: 困境儿童APP | B19: 53000 | C19: 0.35 | D19: =B19*C19 -> 18550 | E19: 叶曼茹 | F19: 0.1 | G19: =L19*F19 -> 371 | H19: 1 | I19: 1 | J19: 刘琳琳 | K19: 0.07 | L19: =B19*K19 -> 3710 | M19: =L19/H19 -> 3710 | N19: =M19/I19 -> 3710 | O19: =8000*H19*I19+G19+L19 -> 12081 | P19: =D19-O19 -> 6469 | Q19: 郑州 | R19: 袁世杰 | S19: 46126 | T19: 46128 | U19: 45工作日 | V19: =WORKDAY(T19,SUBSTITUTE(U19,"工作日","")) -> 46191 | W19: 46198 | X19: 26500 | Y19: 15900 | Z19: 10600 | AA19: ~ | AB19: 50%30%20%
A20: AI留学文书APP | B20: 140000 | C20: 0.35 | D20: =B20*C20 -> 49000 | E20: 邓智婷 | F20: 0.1 | G20: =L20*F20 -> 1400 | H20: 2 | I20: 1 | J20: 段雪婷 | K20: 0.1 | L20: =B20*K20 -> 14000 | M20: =L20/H20 -> 7000 | N20: =M20/I20 -> 7000 | O20: =8000*H20*I20+G20+L20 -> 31400 | P20: =D20-O20 -> 17600 | Q20: 深圳一 | R20: 彭榜其 | S20: 46129 | U20: 35工作日 | X20: 70000 | Y20: 42000 | AA20: ~ | AB20: 50%30%20%
A21: 英文单词背诵小程序 | B21: 14270 | C21: 0.35 | D21: =B21*C21 -> 4994.5 | E21: 于世雯 | F21: 0.07 | G21: =L21*F21 -> 29.967 | H21: 2 | I21: 1 | J21: 张云稳+李耀男 | K21: 0.03 | L21: =B21*K21 -> 428.1 | M21: =L21/H21 -> 214.05 | N21: =M21/I21 -> 214.05 | O21: =8000*H21*I21+G21+L21 -> 16458.067 | P21: =D21-O21 -> -11463.567 | Q21: 郑州 | R21: 宋万里 | S21: 46135 | T21: 46160 | U21: 15工作日 | V21: =WORKDAY(T21,SUBSTITUTE(U21,"工作日","")) -> 46181 | W21: 46228 | X21: 7135 | Y21: 4281 | Z21: 2854 | AA21: ~ | AB21: 50%30%20%
A22: 排队返现小程序 | B22: 18000 | C22: 0.35 | D22: =B22*C22 -> 6300 | E22: 张云稳 | F22: 0 | G22: =L22*F22 -> 0 | H22: 2 | I22: 1 | J22: 张云稳+李耀男 | K22: 0.05 | L22: =B22*K22 -> 900 | M22: =L22/H22 -> 450 | N22: =M22/I22 -> 450 | O22: =8000*H22*I22+G22+L22 -> 16900 | P22: =D22-O22 -> -10600 | Q22: 郑州 | R22: 宋万里 | S22: 46137 | T22: 46156 | U22: 15工作日 | V22: =WORKDAY(T22,SUBSTITUTE(U22,"工作日","")) -> 46177 | W22: 46193 | X22: 7200 | Y22: 5400 | Z22: 5400 | AA22: ~ | AB22: 40%30%30%
A23: 街舞原型图 | B23: 5000 | C23: 0.35 | D23: =B23*C23 -> 1750 | E23: 段雪婷 | F23: 0 | G23: =L23*F23 -> 0 | H23: 1 | I23: 0.25 | J23: 段雪婷 | K23: 0.03 | L23: =B23*K23 -> 150 | M23: =L23/H23 -> 150 | N23: =M23/I23 -> 600 | O23: =8000*H23*I23+G23+L23 -> 2150 | P23: =D23-O23 -> -400 | Q23: 郑州 | R23: 王肖宇/何建新 | S23: 46140 | T23: 46140 | U23: 3工作日 | V23: =WORKDAY(T23,SUBSTITUTE(U23,"工作日","")) -> 46143 | W23: 46142 | X23: 3000 | Y23: 2000 | Z23: ~ | AA23: ~ | AB23: 60%40%
A24: ↘街舞原型图-S1增项 | B24: 1200 | C24: 0.35 | D24: =B24*C24 -> 420 | E24: 段雪婷 | F24: 0 | G24: =L24*F24 -> 0 | H24: 1 | I24: 0.25 | J24: 段雪婷 | K24: 0.05 | L24: =B24*K24 -> 60 | M24: =L24/H24 -> 60 | N24: =M24/I24 -> 240 | O24: =8000*H24*I24+G24+L24 -> 2060 | P24: =D24-O24 -> -1640 | Q24: 郑州 | R24: 王肖宇/何建新 | S24: 46142 | T24: 46142 | U24: 1工作日 | V24: =WORKDAY(T24,SUBSTITUTE(U24,"工作日","")) -> 46143 | W24: 46142 | X24: 1200 | Y24: ~ | Z24: ~ | AA24: ~ | AB24: 1
A25: 企业微信智能客服 | B25: 6000 | C25: 0.35 | D25: =B25*C25 -> 2100 | E25: 任康源 | F25: 0 | G25: =L25*F25 -> 0 | H25: 1 | I25: 0.25 | J25: 任康源 | K25: 0.03 | L25: =B25*K25 -> 180 | M25: =L25/H25 -> 180 | N25: =M25/I25 -> 720 | O25: =8000*H25*I25+G25+L25 -> 2180 | P25: =D25-O25 -> -80 | Q25: 杭二 | R25: 董耀恒 | S25: 46141 | U25: 25工作日 | V25: 46141 | W25: 46203 | X25: 1800 | Y25: 4200 | Z25: ~ | AA25: ~ | AB25: 30%70%
A26: ↘企业微信智能客服增项S1 | B26: 6000 | C26: 0.35 | D26: =B26*C26 -> 2100 | E26: 任康源 | F26: 0 | G26: =L26*F26 -> 0 | H26: 1 | I26: 0.25 | J26: 任康源 | K26: 0.03 | L26: =B26*K26 -> 180 | M26: =L26/H26 -> 180 | N26: =M26/I26 -> 720 | O26: =8000*H26*I26+G26+L26 -> 2180 | P26: =D26-O26 -> -80 | Q26: 杭二 | R26: 董耀恒 | S26: 46141 | U26: 25工作日 | V26: 46141 | W26: 46203 | X26: 4200 | Y26: 1800 | Z26: ~ | AA26: ~ | AB26: 70%30%
A27: ↘企业微信智能客服增项S2 | B27: 2000 | C27: 0.35 | D27: =B27*C27 -> 700 | E27: 任康源 | F27: 0 | G27: =L27*F27 -> 0 | H27: 1 | I27: 0.25 | J27: 任康源 | K27: 0.03 | L27: =B27*K27 -> 60 | M27: =L27/H27 -> 60 | N27: =M27/I27 -> 240 | O27: =8000*H27*I27+G27+L27 -> 2060 | P27: =D27-O27 -> -1360 | Q27: 杭二 | R27: 董耀恒 | S27: 46186 | U27: 25工作日 | V27: 46186 | W27: 46203 | X27: 2000 | Y27: ~ | Z27: ~ | AA27: ~ | AB27: 70%30%
A28: 数据录入app-2026维护费 | B28: 2000 | C28: 0.35 | D28: =B28*C28 -> 700 | E28: 李浩田 | F28: 0 | G28: =L28*F28 -> 0 | H28: 1 | I28: 12 | J28: 张云稳 | K28: 0.03 | L28: =B28*K28 -> 60 | M28: =L28/H28 -> 60 | N28: =M28/I28 -> 5 | O28: =8000*H28*I28+G28+L28 -> 96060 | P28: =D28-O28 -> -95360 | Q28: 北京 | R28: 张春宇 | S28: 46151 | U28: 0工作日 | V28: 46515 | X28: 2000 | Y28: ~ | Z28: ~ | AA28: ~ | AB28: 1 | AC28: 全年维护费
A29: 企业服务小程序 | B29: 50000 | C29: 0.35 | D29: =B29*C29 -> 17500 | E29: 王倩倩 | F29: 0.05 | G29: =L29*F29 -> 175 | H29: 2 | I29: 1 | J29: 张云稳 | K29: 0.07 | L29: =B29*K29 -> 3500 | M29: =L29/H29 -> 1750 | N29: =M29/I29 -> 1750 | O29: =8000*H29*I29+G29+L29 -> 19675 | P29: =D29-O29 -> -2175 | Q29: 郑州 | R29: 袁世杰 | S29: 46156 | U29: 35工作日 | X29: 15000 | AB29: 30%30%30%10%
A30: SERA认知计算系统-AI | B30: 80000 | C30: 0.35 | D30: =B30*C30 -> 28000 | E30: 刘琳琳 | F30: 0 | G30: =L30*F30 -> 0 | H30: 1 | I30: 1 | J30: 刘琳琳 | K30: 0.07 | L30: =B30*K30 -> 5600 | M30: =L30/H30 -> 5600 | N30: =M30/I30 -> 5600 | O30: =8000*H30*I30+G30+L30 -> 13600 | P30: =D30-O30 -> 14400 | Q30: 深圳 | R30: 刘清鸿+龙跃平 | S30: 46163 | T30: 46175 | U30: 47工作日 | V30: =WORKDAY(T30,SUBSTITUTE(U30,"工作日","")) -> 46240 | X30: 24000 | Y30: 16000 | Z30: 24000 | AB30: 30%20%30%20%
A31: HelmMind AI | B31: 110000 | C31: 0.35 | D31: =B31*C31 -> 38500 | E31: 彭崇 | F31: 0.1 | G31: =L31*F31 -> 1100 | H31: 1 | I31: 1 | J31: 任康源 | K31: 0.1 | L31: =B31*K31 -> 11000 | M31: =L31/H31 -> 11000 | N31: =M31/I31 -> 11000 | O31: =8000*H31*I31+G31+L31 -> 20100 | P31: =D31-O31 -> 18400 | Q31: 上海 | R31: 欧秀丽 | S31: 46167 | U31: 50工作日 | X31: 33000 | Y31: 33000 | AB31: 30%20%30%20%
A32: ↘HelmMind AI-维护合同 | B32: 10000 | C32: 0.35 | D32: =B32*C32 -> 3500 | E32: 彭崇 | F32: 0 | G32: =L32*F32 -> 0 | H32: 1 | I32: 1 | J32: 任康源 | K32: 0.1 | L32: =B32*K32 -> 1000 | M32: =L32/H32 -> 1000 | N32: =M32/I32 -> 1000 | O32: =8000*H32*I32+G32+L32 -> 9000 | P32: =D32-O32 -> -5500 | Q32: 上海 | R32: 欧秀丽 | S32: 46167 | U32: 50工作日 | X32: 3300 | AB32: 30%20%30%20%
A33: ↘HelmMind AI-S1 | B33: 50000 | C33: 0.35 | D33: =B33*C33 -> 17500 | E33: 彭崇 | F33: 0.1 | G33: =L33*F33 -> 500 | H33: 1 | I33: 1 | J33: 任康源 | K33: 0.1 | L33: =B33*K33 -> 5000 | M33: =L33/H33 -> 5000 | N33: =M33/I33 -> 5000 | O33: =8000*H33*I33+G33+L33 -> 13500 | P33: =D33-O33 -> 4000 | Q33: 上海 | R33: 欧秀丽 | S33: 46188 | U33: 20工作日 | X33: 15000 | Y33: 15000 | AB33: 30%30%20%20%
A34: JP房产管理APP | B34: 59800 | C34: 0.35 | D34: =B34*C34 -> 20930 | E34: 段雪婷 | F34: 0 | G34: =L34*F34 -> 0 | H34: 1 | I34: 1 | J34: 段雪婷 | K34: 0.07 | L34: =B34*K34 -> 4186 | M34: =L34/H34 -> 4186 | N34: =M34/I34 -> 4186 | O34: =人员工资!H2*H34*I34+G34+L34 -> 9186 | P34: =D34-O34 -> 11744 | Q34: 郑州 | R34: 邵广闯 | S34: 46171 | T34: 46211 | U34: 60工作日 | V34: =WORKDAY(T34,SUBSTITUTE(U34,"工作日","")) -> 46295 | X34: 17940 | Y34: 17940 | AB34: 30%30%30%10%
A35: ↘JP房产管理APP-S1 | B35: 8900 | C35: 0.35 | D35: =B35*C35 -> 3115 | E35: 段雪婷 | F35: 0 | G35: =L35*F35 -> 0 | H35: 1 | I35: 0.5 | J35: 段雪婷 | K35: 0.07 | L35: =B35*K35 -> 623 | M35: =L35/H35 -> 623 | N35: =M35/I35 -> 1246 | O35: =人员工资!H3*H35*I35+G35+L35 -> 3623 | P35: =D35-O35 -> -508 | Q35: 郑州 | R35: 邵广闯 | S35: 46212 | U35: 10工作日 | X35: 8900 | Y35: ~ | Z35: ~ | AA35: ~ | AB35: 1
A36: 问诊小程序 | B36: 12000 | C36: 0.35 | D36: =B36*C36 -> 4200 | E36: 王灿智 | F36: 0 | G36: =L36*F36 -> 0 | H36: 1 | I36: 1 | J36: 原粼→李耀男 | K36: 0.03 | L36: =B36*K36 -> 360 | M36: =L36/H36 -> 360 | N36: =M36/I36 -> 360 | O36: =8000*H36*I36+G36+L36 -> 8360 | P36: =D36-O36 -> -4160 | Q36: 郑州 | R36: 郭嘉宁 | S36: 46115 | U36: 30工作日 | X36: 6000 | Y36: 3600 | AA36: ~ | AB36: 50%30%20%
A37: 二维码程序 | B37: 6000 | C37: 0.35 | D37: =B37*C37 -> 2100 | E37: 张云稳 | F37: 0 | G37: =L37*F37 -> 0 | H37: 1 | I37: 0.04 | J37: 张云稳 | K37: 0.03 | L37: =B37*K37 -> 180 | M37: =L37/H37 -> 180 | N37: =M37/I37 -> 4500 | O37: =8000*H37*I37+G37+L37 -> 500 | P37: =D37-O37 -> 1600 | Q37: 郑州 | R37: 徐英 | S37: 46173 | T37: 46174 | U37: 2工作日 | V37: =WORKDAY(T37,SUBSTITUTE(U37,"工作日","")) -> 46176 | W37: 46176 | X37: 3000 | Y37: 3000 | Z37: ~ | AA37: ~ | AB37: 50%50%
A38: KOL建联管理平台 | B38: 89500 | C38: 0.35 | D38: =B38*C38 -> 31325 | E38: 何世祯 | F38: 0.07 | G38: =L38*F38 -> 438.55 | H38: 1 | I38: 1 | J38: 张云稳 | K38: 0.07 | L38: =B38*K38 -> 6265 | M38: =L38/H38 -> 6265 | N38: =M38/I38 -> 6265 | O38: =8000*H38*I38+G38+L38 -> 14703.55 | P38: =D38-O38 -> 16621.45 | Q38: 上海 | R38: 贺千名/袁晟 | S38: 46184 | T38: 46211 | U38: 50工作日 | V38: =WORKDAY(T38,SUBSTITUTE(U38,"工作日","")) -> 46281 | X38: 26850 | Y38: 17900 | AB38: 30%20%20%20%10%
A39: 电动车租赁页面 | B39: 6000 | C39: 0.35 | D39: =B39*C39 -> 2100 | E39: 李耀男 | F39: 0 | G39: =L39*F39 -> 0 | H39: 1 | I39: 1 | J39: 李耀男 | K39: 0.03 | L39: =B39*K39 -> 180 | M39: =L39/H39 -> 180 | N39: =M39/I39 -> 180 | O39: =8000*H39*I39+G39+L39 -> 8180 | P39: =D39-O39 -> -6080 | Q39: 郑州 | R39: 贾玉龙 6/张振华 4 | S39: 46199 | U39: 20工作日 | V39: =WORKDAY(T39,SUBSTITUTE(U39,"工作日","")) -> 27 | X39: 3000 | Y39: 1800 | AA39: ~ | AB39: 50%30%20%
A40: The Second University | B40: 20200 | C40: 0.35 | D40: =B40*C40 -> 7070 | E40: 叶曼茹 | F40: 0.07 | G40: =L40*F40 -> 70.7 | H40: 1 | I40: 1 | J40: 任康源 | K40: 0.05 | L40: =B40*K40 -> 1010 | M40: =L40/H40 -> 1010 | N40: =M40/I40 -> 1010 | O40: =人员工资!H7*H40*I40+G40+L40 -> 6580.7 | P40: =D40-O40 -> 489.3 | Q40: 郑州 | R40: 王自强 | S40: 46202 | U40: 18工作日 | V40: =WORKDAY(T40,SUBSTITUTE(U40,"工作日","")) -> 25 | X40: 9500 | AA40: ~ | AB40: 50%30%20%
...

Sheet 一部遗留项目
A1: 项目名称 | B1: 项目金额 | C1: 项目成本比例 | D1: 项目成本红线 | E1: UIUE | F1: 产品提成比例 | G1: 产品提成金额 | H1: 开发人员数量 | I1: 项目周期（月） | J1: 开发人员 | K1: 开发奖金比例 | L1: 开发奖金池 | M1: 开发每人奖金 | N1: 开发每人每月奖金 | O1: 项目实际成本 | P1: 项目预估利润 | Q1: 地区 | R1: 商务经理 | S1: 项目签单时间 | T1: UI确认时间 | U1: 工期 | V1: 理论验收日期 | W1: 实际交付日期 | X1: 已回款1 | Y1: 已回款2 | Z1: 已回款3 | AA1: 已回款4 | AB1: 付款方式 | AC1: 备注 | AD1: IP
A2: 标线智汇 | B2: 140000 | C2: 0.35 | D2: =B2*C2 -> 49000 | F2: 0 | G2: =B2*F2 -> 0 | H2: 1 | I2: 1 | J2: 张云稳 | K2: 0.05 | L2: =B2*K2 -> 7000 | M2: =L2/H2 -> 7000 | N2: =M2/I2 -> 7000 | O2: =8000*H2*I2+G2+L2 -> 15000 | P2: =D2-O2 -> 34000 | X2: ~ | Y2: 98000 | AA2: ~ | AB2: ~ | AC2: 小程序APP已上线，功能已开发完成，客户验收修改问题中 | AD2: 已上线
A3: 香港医疗预约APP | B3: 90000 | C3: 0.35 | D3: =B3*C3 -> 31500 | F3: 0 | G3: =B3*F3 -> 0 | H3: 1 | I3: 1 | J3: 张云稳 | K3: 0.05 | L3: =B3*K3 -> 4500 | M3: =L3/H3 -> 4500 | N3: =M3/I3 -> 4500 | O3: =8000*H3*I3+G3+L3 -> 12500 | P3: =D3-O3 -> 19000 | X3: 81000 | Y3: ~ | Z3: ~ | AA3: 9000 | AB3: ~ | AC3: 客户已验收，用户测试中，香港支付宝微信支付待客户开通后对接 | AD3: 验收完成
A4: 秒律师APP+小程序 | B4: 80000 | C4: 0.35 | D4: =B4*C4 -> 28000 | F4: 0 | G4: =B4*F4 -> 0 | H4: 1 | I4: 1 | J4: 任康源 | K4: 0.05 | L4: =B4*K4 -> 4000 | M4: =L4/H4 -> 4000 | N4: =M4/I4 -> 4000 | O4: =8000*H4*I4+G4+L4 -> 12000 | P4: =D4-O4 -> 16000 | X4: 32000 | Y4: 24000 | Z4: 16000 | AA4: 8000 | AB4: ~ | AC4: 3月已交付验收，预计下周收回尾款 | AD4: 3月交付
A5: 海外APP项目 | B5: 55000 | C5: 0.35 | D5: =B5*C5 -> 19250 | F5: 0 | G5: =B5*F5 -> 0 | H5: 1 | I5: 1 | J5: 任康源 | K5: 0.05 | L5: =B5*K5 -> 2750 | M5: =L5/H5 -> 2750 | N5: =M5/I5 -> 2750 | O5: =8000*H5*I5+G5+L5 -> 10750 | P5: =D5-O5 -> 8500 | X5: 22000 | Y5: ~ | Z5: ~ | AA5: ~ | AB5: ~ | AC5: UI阶段，客户认为首页设计与别的APP相似，担心审核问题，还在沟通 | AD5: UI阶段
A6: 蔬菜批发商城 | B6: 82000 | C6: 0.35 | D6: =B6*C6 -> 28700 | F6: 0 | G6: =B6*F6 -> 0 | H6: 1 | I6: 1 | J6: 任康源 | K6: 0.05 | L6: =B6*K6 -> 4100 | M6: =L6/H6 -> 4100 | N6: =M6/I6 -> 4100 | O6: =8000*H6*I6+G6+L6 -> 12100 | P6: =D6-O6 -> 16600 | X6: 82000 | Y6: ~ | Z6: ~ | AA6: ~ | AB6: ~ | AC6: 纯增项项目，UI阶段，客户住院项目暂时停滞 | AD6: UI阶段
A7: 海运服务平台 | B7: 45000 | C7: 0.35 | D7: =B7*C7 -> 15750 | F7: 0 | G7: =B7*F7 -> 0 | H7: 1 | I7: 1 | J7: 任康源 | K7: 0.05 | L7: =B7*K7 -> 2250 | M7: =L7/H7 -> 2250 | N7: =M7/I7 -> 2250 | O7: =8000*H7*I7+G7+L7 -> 10250 | P7: =D7-O7 -> 5500 | X7: 22500 | Y7: 13500 | Z7: 9000 | AA7: ~ | AB7: ~ | AC7: 开发完成，2026.4.24已签结项函，预计下周尾款到账 | AD7: 开发完成
A8: 批发商城平台APP | B8: 136000 | C8: 0.35 | D8: =B8*C8 -> 47600 | F8: 0 | G8: =B8*F8 -> 0 | H8: 1 | I8: 1 | J8: 任康源 | K8: 0.05 | L8: =B8*K8 -> 6800 | M8: =L8/H8 -> 6800 | N8: =M8/I8 -> 6800 | O8: =8000*H8*I8+G8+L8 -> 14800 | P8: =D8-O8 -> 32800 | X8: 48000 | Y8: 60800 | Z8: 27200 | AA8: ~ | AB8: ~ | AC8: 3月底交付验收，客户反馈缓慢，每周催促中无反馈，争取5月收回尾款 | AD8: 3月底交付
A9: 楼盘信息发布平台 | B9: 43800 | C9: 0.35 | D9: =B9*C9 -> 15330 | F9: 0 | G9: =B9*F9 -> 0 | H9: 1 | I9: 1 | J9: 任康源 | K9: 0.05 | L9: =B9*K9 -> 2190 | M9: =L9/H9 -> 2190 | N9: =M9/I9 -> 2190 | O9: =8000*H9*I9+G9+L9 -> 10190 | P9: =D9-O9 -> 5140 | X9: 17520 | Y9: 17520 | Z9: 8800 | AA9: ~ | AB9: ~ | AC9: 部分接口需客户提供，等待中未给出具体提供时间 | AD9: 等接口
A10: 民赢APP | B10: 15000 | C10: 0.35 | D10: =B10*C10 -> 5250 | F10: 0 | G10: =B10*F10 -> 0 | H10: 1 | I10: 1 | J10: 任康源 | K10: 0.05 | L10: =B10*K10 -> 750 | M10: =L10/H10 -> 750 | N10: =M10/I10 -> 750 | O10: =8000*H10*I10+G10+L10 -> 8750 | P10: =D10-O10 -> -3500 | X10: 7500 | Y10: 4500 | AA10: ~ | AB10: 50%30%20% | AC10: 项目严重停滞，客户失联，商务也无法联系，回款时间无法确定 | AD10: 严重停滞
A11: 伊拉克餐饮商城 | B11: 120000 | C11: 0.35 | D11: =B11*C11 -> 42000 | F11: 0 | G11: =B11*F11 -> 0 | H11: 1 | I11: 1 | J11: 任康源 | K11: 0.05 | L11: =B11*K11 -> 6000 | M11: =L11/H11 -> 6000 | N11: =M11/I11 -> 6000 | O11: =8000*H11*I11+G11+L11 -> 14000 | P11: =D11-O11 -> 28000 | X11: 48000 | Y11: 36000 | AB11: 40%30%20%10% | AC11: 项目停滞，等待第三方开发人员提供接口，未给出具体日期 | AD11: 停滞
A12: 机动车检测预约小程序 | B12: 10000 | C12: 0.35 | D12: =B12*C12 -> 3500 | F12: 0 | G12: =B12*F12 -> 0 | H12: 1 | I12: 1 | J12: 李浩田 | K12: 0.05 | L12: =B12*K12 -> 500 | M12: =L12/H12 -> 500 | N12: =M12/I12 -> 500 | O12: =8000*H12*I12+G12+L12 -> 8500 | P12: =D12-O12 -> -5000 | X12: 7000 | Z12: ~ | AA12: ~ | AB12: ~ | AC12: 下周应可结束
A13: 极境本草中药饮片商城 | B13: 25000 | C13: 0.35 | D13: =B13*C13 -> 8750 | F13: 0 | G13: =B13*F13 -> 0 | H13: 1 | I13: 1 | J13: 李浩田 | K13: 0.05 | L13: =B13*K13 -> 1250 | M13: =L13/H13 -> 1250 | N13: =M13/I13 -> 1250 | O13: =8000*H13*I13+G13+L13 -> 9250 | P13: =D13-O13 -> -500 | X13: 7500 | Y13: 15000 | Z13: 2500 | AA13: ~ | AB13: ~ | AC13: 客户域名未过，预计到5月
A14: 东出活动小程序 | B14: 55000 | C14: 0.35 | D14: =B14*C14 -> 19250 | F14: 0 | G14: =B14*F14 -> 0 | H14: 1 | I14: 1 | J14: 李浩田 | K14: 0.05 | L14: =B14*K14 -> 2750 | M14: =L14/H14 -> 2750 | N14: =M14/I14 -> 2750 | O14: =8000*H14*I14+G14+L14 -> 10750 | P14: =D14-O14 -> 8500 | X14: 16500 | Y14: 11000 | Z14: 16500 | AB14: 三期四期共￥27,500，三期款商务说下周能给，四期等客户筹备APP上架
A15: 非洲多商 | B15: 60000 | C15: 0.35 | D15: =B15*C15 -> 21000 | F15: 0 | G15: =B15*F15 -> 0 | H15: 1 | I15: 1 | J15: 李浩田 | K15: 0.05 | L15: =B15*K15 -> 3000 | M15: =L15/H15 -> 3000 | N15: =M15/I15 -> 3000 | O15: =8000*H15*I15+G15+L15 -> 11000 | P15: =D15-O15 -> 10000 | X15: 21000 | Y15: 21000 | AA15: ~ | AB15: ~ | AC15: 商务联系不上客户
A16: 综合APP增项 | B16: 98000 | C16: 0.35 | D16: =B16*C16 -> 34300 | F16: 0 | G16: =B16*F16 -> 0 | H16: 1 | I16: 1 | J16: 李浩田 | K16: 0.05 | L16: =B16*K16 -> 4900 | M16: =L16/H16 -> 4900 | N16: =M16/I16 -> 4900 | O16: =8000*H16*I16+G16+L16 -> 12900 | P16: =D16-O16 -> 21400 | AB16: 客户说付完了，商务要款有点乱，需等周一与商务核对确认
A17: 黄金回收 | B17: 80000 | C17: 0.35 | D17: =B17*C17 -> 28000 | F17: 0 | G17: =B17*F17 -> 0 | H17: 1 | I17: 1 | J17: 任康源 | K17: 0.05 | L17: =B17*K17 -> 4000 | M17: =L17/H17 -> 4000 | N17: =M17/I17 -> 4000 | O17: =8000*H17*I17+G17+L17 -> 12000 | P17: =D17-O17 -> 16000 | X17: 32000 | Y17: 24000 | AB17: 40%30%20%10% | AC17: 技术十三部5/技术十五部5
A18: ↘黄金回收增项S1 | B18: 6000 | C18: 0.35 | D18: =B18*C18 -> 2100 | H18: 1 | I18: 1 | J18: 任康源 | K18: 0.05 | L18: =B18*K18 -> 300 | M18: =L18/H18 -> 300 | N18: =M18/I18 -> 300 | O18: =8000*H18*I18+G18+L18 -> 8300 | P18: =D18-O18 -> -6200 | U18: 7工作日 | X18: 6000 | Y18: ~ | Z18: ~ | AA18: ~ | AB18: ~ | AC18: 技术十三部5/技术十五部5

Sheet 人员工资
A1: 序号 | B1: 姓名 | C1: 入职时间 | D1: 工种 | E1: 级别 | F1: 在职状态 | G1: 是否转正 | H1: 工资 | I1: 保底 | J1: 社保 | K1: 提成 | L1: ROI | M1: 备注
A2: =ROW()-1 -> 1 | B2: 段雪婷 | C2: 46090 | D2: AI应用开发工程师 | E2: 中级 | F2: 在职 | G2: 正式 | H2: 5000 | I2: 1000 | J2: 955 | L2: =K2/(H2+I2+J2+200) -> 0
A3: =ROW()-1 -> 2 | B3: 李祥光 | C3: 46204 | D3: AI应用开发工程师 | E3: 高级 | F3: 在职 | G3: 试用 | H3: 6000 | I3: 1000
A4: =ROW()-1 -> 3 | B4: 李耀男 | C4: 46097 | D4: AI应用开发工程师 | E4: 实习生 | F4: 在职 | G4: 实习 | H4: 1000 | L4: =K4/(H4+I4+J4+200) -> 0
A5: =ROW()-1 -> 4 | B5: 刘琳琳 | C5: 46119 | D5: AI应用开发工程师 | E5: 中级 | F5: 在职 | G5: 试用 | H5: 4500 | I5: 1000 | L5: =K5/(H5+I5+J5+200) -> 0
A6: =ROW()-1 -> 5 | B6: 张云稳 | C6: 45051 | D6: AI应用开发工程师 | E6: 高级 | F6: 在职 | G6: 正式 | H6: 6000 | I6: 1300 | J6: 955 | L6: =K6/(H6+I6+J6+200) -> 0
A7: =ROW()-1 -> 6 | B7: 任康源 | C7: 45425 | D7: AI应用开发工程师 | E7: 中级 | F7: 在职 | G7: 正式 | H7: 5500 | J7: 955 | L7: =K7/(H7+I7+J7+200) -> 0
A8: =ROW()-1 -> 7 | B8: 吴二佩 | C8: 46099 | D8: Vue | E8: 高级 | F8: 离职 | G8: 试用 | H8: 6000 | I8: 1000 | L8: =K8/(H8+I8+J8+200) -> 0 | M8: 3月23日离职
A9: =ROW()-1 -> 8 | B9: 张耘彬 | C9: 46085 | D9: Vue | E9: 实习生 | F9: 离职 | G9: 实习 | H9: 1000 | L9: =K9/(H9+I9+J9+200) -> 0 | M9: 5月6日离职
A10: =ROW()-1 -> 9 | B10: 宋天阳 | C10: 46097 | D10: Python | E10: 实习生 | F10: 离职 | G10: 实习 | H10: 1000 | L10: =K10/(H10+I10+J10+200) -> 0 | M10: 5月8日离职
A11: =ROW()-1 -> 10 | B11: 李浩田 | D11: 前端 | E11: 中级 | F11: 离职 | G11: 正式 | H11: 5000 | J11: 955 | L11: =K11/(H11+I11+J11+200) -> 0 | M11: 5月31日离职
A12: 合计 | H12: =SUMIF(F2:F11,"在职",H2:H11) -> 28000 | I12: =SUMIF(F2:F11,"在职",I2:I11) -> 4300 | J12: =SUMIF(F2:F11,"在职",J2:J11) -> 2865

Sheet 成本核算新表
A1: 项目名称 | B1: 项目金额 | C1: 经费池(35%) | D1: 产品提成比例 | E1: 产品提成金额 | F1: 开发1 | G1: 开发2 | H1: 周期(月) | I1: 月薪合计 | J1: 社保合计 | K1: 人力成本 | L1: 奖金池 | M1: 每人奖金
A2: 报告查询H5 | B2: 3000 | C2: =B2*0.35 -> 1050 | D2: 0 | E2: =B2*D2 -> 0 | F2: 原粼 | H2: 0.33 | I2: =SUMIF(人员工资!B2:B10,F2,人员工资!H2:H10)+SUMIF(人员工资!B2:B10,G2,人员工资!H2:H10) -> 0 | J2: =SUMIF(人员工资!B2:B10,F2,人员工资!J2:J10)+SUMIF(人员工资!B2:B10,G2,人员工资!J2:J10) -> 0 | K2: =(I2+J2)*H2 -> 0 | L2: =C2-E2-K2 -> 1050 | M2: =IF(COUNTA(F2:G2)>0,L2/COUNTA(F2:G2),0) -> 1050
A3: ↘报告查询H5-增项1 | B3: 500 | C3: =B3*0.35 -> 175 | D3: 0 | E3: =B3*D3 -> 0 | F3: 原粼 | H3: 0.05 | I3: =SUMIF(人员工资!B2:B10,F3,人员工资!H2:H10)+SUMIF(人员工资!B2:B10,G3,人员工资!H2:H10) -> 0 | J3: =SUMIF(人员工资!B2:B10,F3,人员工资!J2:J10)+SUMIF(人员工资!B2:B10,G3,人员工资!J2:J10) -> 0 | K3: =(I3+J3)*H3 -> 0 | L3: =C3-E3-K3 -> 175 | M3: =IF(COUNTA(F3:G3)>0,L3/COUNTA(F3:G3),0) -> 175
A4: ↘报告查询H5-增项2 | B4: 2500 | C4: =B4*0.35 -> 875 | D4: 0 | E4: =B4*D4 -> 0 | F4: 原粼 | H4: 0.05 | I4: =SUMIF(人员工资!B2:B10,F4,人员工资!H2:H10)+SUMIF(人员工资!B2:B10,G4,人员工资!H2:H10) -> 0 | J4: =SUMIF(人员工资!B2:B10,F4,人员工资!J2:J10)+SUMIF(人员工资!B2:B10,G4,人员工资!J2:J10) -> 0 | K4: =(I4+J4)*H4 -> 0 | L4: =C4-E4-K4 -> 875 | M4: =IF(COUNTA(F4:G4)>0,L4/COUNTA(F4:G4),0) -> 875
A5: ↘报告查询H5-增项3 | B5: 1000 | C5: =B5*0.35 -> 350 | D5: 0 | E5: =B5*D5 -> 0 | F5: 原粼 | H5: 0.05 | I5: =SUMIF(人员工资!B2:B10,F5,人员工资!H2:H10)+SUMIF(人员工资!B2:B10,G5,人员工资!H2:H10) -> 0 | J5: =SUMIF(人员工资!B2:B10,F5,人员工资!J2:J10)+SUMIF(人员工资!B2:B10,G5,人员工资!J2:J10) -> 0 | K5: =(I5+J5)*H5 -> 0 | L5: =C5-E5-K5 -> 350 | M5: =IF(COUNTA(F5:G5)>0,L5/COUNTA(F5:G5),0) -> 350
A6: AI古玩知识问答 | B6: 22000 | C6: =B6*0.35 -> 7700 | D6: 0.002 | E6: =B6*D6 -> 44 | F6: 张耘彬 | H6: 0.083 | I6: =SUMIF(人员工资!B2:B10,F6,人员工资!H2:H10)+SUMIF(人员工资!B2:B10,G6,人员工资!H2:H10) -> 1000 | J6: =SUMIF(人员工资!B2:B10,F6,人员工资!J2:J10)+SUMIF(人员工资!B2:B10,G6,人员工资!J2:J10) -> 0 | K6: =(I6+J6)*H6 -> 83 | L6: =C6-E6-K6 -> 7573 | M6: =IF(COUNTA(F6:G6)>0,L6/COUNTA(F6:G6),0) -> 7573
A7: ↘AI古玩知识问答-增项1 | B7: 2000 | C7: =B7*0.35 -> 700 | D7: 0.002 | E7: =B7*D7 -> 4 | F7: 张耘彬 | H7: 0.083 | I7: =SUMIF(人员工资!B2:B10,F7,人员工资!H2:H10)+SUMIF(人员工资!B2:B10,G7,人员工资!H2:H10) -> 1000 | J7: =SUMIF(人员工资!B2:B10,F7,人员工资!J2:J10)+SUMIF(人员工资!B2:B10,G7,人员工资!J2:J10) -> 0 | K7: =(I7+J7)*H7 -> 83 | L7: =C7-E7-K7 -> 613 | M7: =IF(COUNTA(F7:G7)>0,L7/COUNTA(F7:G7),0) -> 613
A8: AI会议翻译项目 | B8: 67040 | C8: =B8*0.35 -> 23464 | D8: 0.002 | E8: =B8*D8 -> 134.08 | F8: 张耘彬 | H8: 2 | I8: =SUMIF(人员工资!B2:B10,F8,人员工资!H2:H10)+SUMIF(人员工资!B2:B10,G8,人员工资!H2:H10) -> 1000 | J8: =SUMIF(人员工资!B2:B10,F8,人员工资!J2:J10)+SUMIF(人员工资!B2:B10,G8,人员工资!J2:J10) -> 0 | K8: =(I8+J8)*H8 -> 2000 | L8: =C8-E8-K8 -> 21329.92 | M8: =IF(COUNTA(F8:G8)>0,L8/COUNTA(F8:G8),0) -> 21329.92
A9: AI颜值分析 & 穿搭推荐小程序项目 | B9: 45000 | C9: =B9*0.35 -> 15750 | D9: 0.002 | E9: =B9*D9 -> 90 | F9: 段雪婷 | H9: 1 | I9: =SUMIF(人员工资!B2:B10,F9,人员工资!H2:H10)+SUMIF(人员工资!B2:B10,G9,人员工资!H2:H10) -> 5000 | J9: =SUMIF(人员工资!B2:B10,F9,人员工资!J2:J10)+SUMIF(人员工资!B2:B10,G9,人员工资!J2:J10) -> 955 | K9: =(I9+J9)*H9 -> 5955 | L9: =C9-E9-K9 -> 9705 | M9: =IF(COUNTA(F9:G9)>0,L9/COUNTA(F9:G9),0) -> 9705
A10: AI数据审核分析平台 | B10: 110000 | C10: =B10*0.35 -> 38500 | D10: 0 | E10: =B10*D10 -> 0 | F10: 段雪婷 | H10: 1 | I10: =SUMIF(人员工资!B2:B10,F10,人员工资!H2:H10)+SUMIF(人员工资!B2:B10,G10,人员工资!H2:H10) -> 5000 | J10: =SUMIF(人员工资!B2:B10,F10,人员工资!J2:J10)+SUMIF(人员工资!B2:B10,G10,人员工资!J2:J10) -> 955 | K10: =(I10+J10)*H10 -> 5955 | L10: =C10-E10-K10 -> 32545 | M10: =IF(COUNTA(F10:G10)>0,L10/COUNTA(F10:G10),0) -> 32545
A11: 工信局企业调研小程序 | B11: 5500 | C11: =B11*0.35 -> 1925 | D11: 0 | E11: =B11*D11 -> 0 | F11: 李耀男 | H11: 1 | I11: =SUMIF(人员工资!B2:B10,F11,人员工资!H2:H10)+SUMIF(人员工资!B2:B10,G11,人员工资!H2:H10) -> 1000 | J11: =SUMIF(人员工资!B2:B10,F11,人员工资!J2:J10)+SUMIF(人员工资!B2:B10,G11,人员工资!J2:J10) -> 0 | K11: =(I11+J11)*H11 -> 1000 | L11: =C11-E11-K11 -> 925 | M11: =IF(COUNTA(F11:G11)>0,L11/COUNTA(F11:G11),0) -> 925
A12: Ai医膳智评小程序 | B12: 52750 | C12: =B12*0.35 -> 18462.5 | D12: 0.1 | E12: =B12*D12 -> 5275 | F12: 李浩田 | H12: 1 | I12: =SUMIF(人员工资!B2:B10,F12,人员工资!H2:H10)+SUMIF(人员工资!B2:B10,G12,人员工资!H2:H10) -> 0 | J12: =SUMIF(人员工资!B2:B10,F12,人员工资!J2:J10)+SUMIF(人员工资!B2:B10,G12,人员工资!J2:J10) -> 0 | K12: =(I12+J12)*H12 -> 0 | L12: =C12-E12-K12 -> 13187.5 | M12: =IF(COUNTA(F12:G12)>0,L12/COUNTA(F12:G12),0) -> 13187.5
A13: ↘Ai医膳智评小程序-增项S1 | B13: 1500 | C13: =B13*0.35 -> 525 | D13: 0.1 | E13: =B13*D13 -> 150 | F13: 李浩田 | H13: 1 | I13: =SUMIF(人员工资!B2:B10,F13,人员工资!H2:H10)+SUMIF(人员工资!B2:B10,G13,人员工资!H2:H10) -> 0 | J13: =SUMIF(人员工资!B2:B10,F13,人员工资!J2:J10)+SUMIF(人员工资!B2:B10,G13,人员工资!J2:J10) -> 0 | K13: =(I13+J13)*H13 -> 0 | L13: =C13-E13-K13 -> 375 | M13: =IF(COUNTA(F13:G13)>0,L13/COUNTA(F13:G13),0) -> 375
A14: 二开服务号 | B14: 2000 | C14: =B14*0.35 -> 700 | D14: 0.1 | E14: =B14*D14 -> 200 | F14: 张耘彬 | H14: 1 | I14: =SUMIF(人员工资!B2:B10,F14,人员工资!H2:H10)+SUMIF(人员工资!B2:B10,G14,人员工资!H2:H10) -> 1000 | J14: =SUMIF(人员工资!B2:B10,F14,人员工资!J2:J10)+SUMIF(人员工资!B2:B10,G14,人员工资!J2:J10) -> 0 | K14: =(I14+J14)*H14 -> 1000 | L14: =C14-E14-K14 -> -500 | M14: =IF(COUNTA(F14:G14)>0,L14/COUNTA(F14:G14),0) -> -500
